Workbook

Sheet Config
A1: PROJECT CONFIGURATION — VARIABLE DEFINITIONS
A2: All sheets reference these cells. Change a value here and it propagates everywhere automatically.
A3: SECTION 1 - PROJECT IDENTITY
A4: Variable Name | B4: Value | C4: Unit / Notes | D4: Used In | E4: Updated | F4: Source
A5: ProjectName | B5: Galvanizing System | C5: Project Title | D5: All Sheets | E5: 2026 | F5: Client Brief
A6: ProjectNumber | B6: PRJ-26001 | C6: Project ID | D6: All Sheets – Headers | E6: 2026 | F6: PM System
A7: ClientName | B7: Howest - Cyber3Lab | C7: Client | D7: Cover | E7: 2026 | F7: Contract
A8: SiteLocation | B8: Building J - Cyber3Lab, Howest Brugge, Belgium | C8: Location | D8: Cover, TBL | E8: 2026 | F8: Site Survey
A9: SECTION 2 - PLC PLATFORM (WAGO CC100 751-9402)
A10: Variable Name | B10: Value | C10: Unit / Notes | D10: Used In | E10: Updated | F10: Source
A11: PLCPlatform | B11: WAGO Compact Controller 100 | C11: Brand / Series | D11: Cover, IO List, TBL | E11: 2026 | F11: WAGO 751-9402 Datasheet
A12: PLCModelNo | B12: 751-9402 | C12: Part Number | D12: Cover, IO List, TBL | E12: 2026 | F12: wago.com/global/p/751-9402
A13: PLCProgEnv | B13: CODESYS V3.5 | C13: IDE / Runtime | D13: Cover, Wiring Legend | E13: 2026 | F13: WAGO firmware docs
A14: PLCComms | B14: Modbus TCP, EtherNet/IP, PROFINET, EtherCAT, BACnet, MQTT | C14: Protocols | D14: Cover, Legend | E14: 2026 | F14: WAGO product page
A15: PLCConnType | B15: picoMAX® CAGE CLAMP® push-in | C15: I/O Connector Type | D15: IO List, TBL | E15: 2026 | F15: WAGO datasheet
A16: PLCRating | B16: IP20 / DIN Rail Mount / 24 VDC | C16: Protection / Mounting | D16: Cover, TBL | E16: 2026 | F16: WAGO 751-9402 spec
A17: SECTION 3 - ELECTRICAL SPECIFICATIONS
A18: Variable Name | B18: Value | C18: Unit / Notes | D18: Used In | E18: Updated | F18: Source
A19: VoltageControl | B19: 24 VDC | C19: Control Supply | D19: Cover, IO List, TBL, Legend | E19: 2026 | F19: IEC 60204-1
A20: VoltagePower | B20: 230 V AC, 50 Hz | C20: Main Supply | D20: Cover, TBL | E20: 2026 | F20: Site supply spec
A21: EnclosureRating | B21: IP65 (Field) / IP54 (Panel) | C21: IP Rating | D21: Cover, TBL | E21: 2026 | F21: IEC 60529
A22: SECTION 4 - WAGO CC100 I/O CHANNEL MAP (On-Board I/O)
A23: Variable Name | B23: Value | C23: Unit / Notes | D23: Used In | E23: Updated | F23: Source
A24: I/O Tag | B24: Channel Label | C24: CODESYS Addr | D24: Signal Type | E24: Connector | F24: Notes
A25: DI10001 | B25: DI.1 | C25: %IX0.0 | D25: DI 24VDC | E25: X11 – Pin 1 | F25: On-board: 8 dedicated DI, 2.8 mA
A26: DI10002 | B26: DI.2 | C26: %IX0.1 | D26: DI 24VDC | E26: X11 – Pin 2 | F26: 24 VDC sinking, RC filter 5µs
A27: DI10003 | B27: DI.3 | C27: %IX0.2 | D27: DI 24VDC | E27: X11 – Pin 3
A28: DI10004 | B28: DI.4 | C28: %IX0.3 | D28: DI 24VDC | E28: X11 – Pin 4
A29: DI10005 | B29: DI.5 | C29: %IX0.4 | D29: DI 24VDC | E29: X11 – Pin 5
A30: DI10006 | B30: DI.6 | C30: %IX0.5 | D30: DI 24VDC | E30: X11 – Pin 6
A31: DI10007 | B31: DI.7 | C31: %IX0.6 | D31: DI 24VDC | E31: X11 – Pin 7
A32: DI10008 | B32: DI.8 | C32: %IX0.7 | D32: DI 24VDC | E32: X11 – Pin 8
A33: DI10009 | B33: DIO.1 | C33: %IX1.0 | D33: DI/DO 24VDC | E33: X12 – Pin 1 | F33: 8 configurable DIO; set in CODESYS
A34: DI10010 | B34: DIO.2 | C34: %IX1.1 | D34: DI/DO 24VDC | E34: X12 – Pin 2 | F34: Configure as DI or DO per channel
A35: DI10011 | B35: DIO.3 | C35: %IX1.2 | D35: DI/DO 24VDC | E35: X12 – Pin 3
A36: DI10012 | B36: DIO.4 | C36: %IX1.3 | D36: DI/DO 24VDC | E36: X12 – Pin 4
A37: DO20001 | B37: DIO.5 | C37: %QX1.4 | D37: DO 24VDC | E37: X12 – Pin 5 | F37: Configured as DO, 0.5 A max
A38: DO20002 | B38: DIO.6 | C38: %QX1.5 | D38: DO 24VDC | E38: X12 – Pin 6
A39: DO20003 | B39: DIO.7 | C39: %QX1.6 | D39: DO 24VDC | E39: X12 – Pin 7
A40: DO20004 | B40: DIO.8 | C40: %QX1.7 | D40: DO 24VDC | E40: X12 – Pin 8
...

Sheet Cover
B1: INDUSTRIAL PLC CABLING & WIRING SYSTEM
B2: Project Documentation Package
B4: PROJECT INFORMATION
B5: Project Name: | C5: =Config!B5 -> Galvanizing System | D5: Project No.: | E5: =Config!B6 -> PRJ-26001
B6: Client: | C6: =Config!B7 -> Howest - Cyber3Lab | D6: Site Location: | E6: =Config!B8 -> Building J - Cyber3Lab, Howest Brugge, Belgium
B7: Engineer: | C7: =Config!B61 -> Attila Peter Szucs | D7: Discipline: | E7: =Config!B62 -> Electrical / Instrumentation
B8: Drawing Ref: | C8: =Config!B57 -> EL-PLC-001 to EL-PLC-048 | D8: PLC Platform: | E8: =Config!B11&" ("&Config!B12&")" -> WAGO Compact Controller 100 (751-9402)
B9: Voltage (Control): | C9: =Config!B19 -> 24 VDC | D9: Voltage (Power): | E9: =Config!B20 -> 230 V AC, 50 Hz
B10: Enclosure Rating: | C10: =Config!B21 -> IP65 (Field) / IP54 (Panel) | D10: Standard: | E10: IEC 60204-1 / AS/NZS 3000
B11: Prepared By: | C11: =Config!B58 -> Howest - Cyber3Lab | D11: Date:
B12: Approved By: | C12: =Config!B59 -> Laurens Singier | D12: Rev Status: | E12: =Config!B60 -> REV A - Issued for Construction
B14: DOCUMENT INDEX
B15: Sheet / Tab | C15: Document Title | D15: Description | E15: Status
B16: Cover | C16: Project Cover Sheet | D16: Project information and document index
B17: Cable Schedule | C17: Cable Schedule | D17: Full cable listing with specs, routing & terminations
B18: IO List | C18: PLC I/O List | D18: Digital and analog I/O assignments with signal details
B19: Terminal Block Layout | C19: Terminal Block Layout | D19: Panel terminal block assignments and wire mapping
B20: Cable Drum Register | C20: Cable Drum Register | D20: Drum tracking, lengths issued and remaining
B21: Wiring Legend | C21: Wiring Legend & Standards | D21: Color codes, abbreviations, cable types, standards ref
B23: GENERAL NOTES
B24: 1. All cabling shall be installed in accordance with IEC 60204-1 and local wiring regulations.
B25: 2. Signal cables (4–20 mA) must be segregated from power cables (minimum 200 mm separation).
B26: 3. All cable screens/shields to be grounded at ONE end only (control panel end) unless otherwise noted.
B27: 4. Minimum cable bending radius: 6× cable OD (multi-core), 8× cable OD (armoured).
B28: 5. All field terminations to use ferrules (bootlace type). Crimping tool: Weidmuller or equivalent.
B29: 6. WAGO CC100 I/O: 8 DI (X12), 8 configurable DIO (X5), 2 AI + 2 AIO (X6), 2 NI/PT (X13). All on-board; 24 VDC.
B30: 7. Motor cables must be shielded (VFD duty) where inverter drives are installed.

Sheet Cable Schedule
A1: ="CABLE SCHEDULE — "&Config!B6 -> CABLE SCHEDULE — PRJ-26001
A2: ="Project: "&Config!B6&" | Project No: "&Config!B6&" | PLC: "&Config!B11&" ("&Config!B12&") | Rev: "&Config!B60 -> Project: PRJ-26001 | Project No: PRJ-26001 | PLC: WAGO Compact Controller 100 (751-9402) | Rev: REV A - Issued for Construction
A3: # | B3: Cable No. | C3: From (Source) | D3: From Location | E3: From Terminal | F3: To (Destination) | G3: To Location | H3: To Terminal | I3: Cable Type | J3: Cores | K3: Size mm² | L3: Volt Rating | M3: Shield | N3: Length m | O3: Conduit / Tray | P3: Status | Q3: Rev
A4: 1 | B4: NET-W101 | C4: WAGO 852-1812 | D4: Panel Cabinet | E4: X3 | F4: WAGO CC100 751-9402 | G4: Panel Cabinet | H4: X1 | I4: SF/UTP Cat6a | J4: 4P | K4: 24 AWG | L4: 100V | M4: No | N4: 50 cm | P4: Installed | Q4: C
A5: 2 | B5: NET-W102 | C5: WAGO 852-1812 | D5: Panel Cabinet | E5: X1 | F5: EXT_NETWORK_UPLINK | G5: External | H5: - | I5: SF/UTP Cat6a | J5: 4P | K5: 24 AWG | L5: 100V | M5: No | N5: 3 m | P5: Installed | Q5: C
A6: 3 | B6: NET-W103 | C6: WAGO 852-1812 | D6: Panel Cabinet | E6: X8 | F6: EXT_SERVICE_CON | G6: External | H6: - | I6: SF/UTP Cat6a | J6: 4P | K6: 24 AWG | L6: 100V | M6: No | N6: 2 m | P6: Installed | Q6: C
A7: 4 | B7: NET-W104 | C7: WAGO 852-1812 | D7: Panel Cabinet | E7: X2 | F7: WAGO Web Panel 400 (A1) | G7: Panel Cabinet | H7: X1:ETH | I7: SF/UTP Cat6a | J7: 4P | K7: 24 AWG | L7: 100V | M7: No | N7: 2 m | P7: Installed | Q7: C
A8: 5 | B8: PWR-W10 | C8: Power Outlet (230V AC) | D8: Panel Cabinet | E8: X1 (L/N/PE) | F8: G1 - QUINT POWER AC/DC Converter | G8: Panel Cabinet | H8: X10 | I8: ÖLFLEX CLASSIC 100 | J8: 3G | K8: 1.5 mm² | L8: 300/500V | M8: No | N8: 3 m | P8: Installed | Q8: C
A9: 6 | B9: PWR-W11 | C9: Power Outlet (230V AC) | D9: Panel Cabinet | E9: X2 (L/N/PE) | F9: G2 - WAGO 787-1202 AC/DC Converter | G9: Panel Cabinet | H9: X10 | I9: ÖLFLEX CLASSIC 100 | J9: 3G | K9: 1.5 mm² | L9: 100/240V | M9: No | N9: 1.9 m | P9: Installed | Q9: C
A10: 7 | B10: PWR-W13 | C10: 24V DC Distribution Block (X24V) | D10: Panel Cabinet | E10: 24V_PLC_1 / 0V_PLC_1 | F10: WAGO CC100 751-9402 (KF10) | G10: Panel Cabinet | H10: 86.1 / 86.2 | I10: 2xAWG20 | J10: 2 | K10: 0.5 mm² | L10: 24V DC | M10: No | N10: 50 cm | P10: Installed | Q10: C
A11: 8 | B11: PWR-W14 | C11: 24V DC Distribution Block (X24V) | D11: Panel Cabinet | E11: 24V_SW1 / 0V_SW1 | F11: WAGO 852-1812 Switch (KF1) | G11: Panel Cabinet | H11: PWR+ / PWR- | I11: 2xAWG20 | J11: 2 | K11: 0.5 mm² | L11: 24V DC | M11: No | N11: 30 cm | P11: Installed | Q11: C
A12: 9 | B12: PWR-W15 | C12: 24V DC Distribution Block (X0V) | D12: Panel Cabinet | E12: +-24V_PLC_X5:1 / +-0V_PLC_X5:2 | F12: WAGO CC100 751-9402 (KF10) | G12: Panel Cabinet | H12: X5 (DIO power) | I12: 2xAWG20 | J12: 2 | K12: 0.5 mm² | L12: 24V DC | M12: No | N12: 25 cm | P12: Installed | Q12: C
A13: 10 | B13: HMI-W12 | C13: 24V DC Distribution Block (X24V) | D13: Panel Cabinet | E13: +-24V_HMI_1 / +-0V_HMI_1 / +-PE_HMI_1 | F13: WAGO Web Panel 400 (A1) | G13: Panel Cabinet | H13: X3.1 / X3.2 / X3.3 | I13: 3xAWG20 | J13: 3 | K13: 0.5 mm² | L13: 24V DC | M13: No | N13: 30 cm | P13: Installed | Q13: C
A14: 11 | B14: PLC-W10 | C14: 0V DC Distribution Block (X0V) | D14: Panel Cabinet | E14: +-0V_PLC_X12:2 | F14: WAGO CC100 751-9402 (KF10) | G14: Panel Cabinet | H14: X12.2 (0V ref) | I14: 1xAWG20 | J14: 1 | K14: 0.5 mm² | L14: 24V DC | M14: No | N14: 50 cm | P14: Installed | Q14: C
A15: 12 | B15: PLC-W11 | C15: 24V DC Distribution Block (X24V) | D15: Panel Cabinet | E15: +-24V_PLC_X12:3 | F15: S1 - E-Stop / Control Button | G15: Panel Cabinet | H15: COM | I15: 1xAWG20 | J15: 1 | K15: 0.5 mm² | L15: 24V DC | M15: No | N15: 50 cm | P15: Installed | Q15: C
A16: 13 | B16: PLC-W12 | C16: WAGO CC100 751-9402 (KF10) | D16: Panel Cabinet | E16: X12.3 (DI input) | F16: S1 - E-Stop / Control Button | G16: Panel Cabinet | H16: NO | I16: 1xAWG20 | J16: 1 | K16: 0.5 mm² | L16: 24V DC | M16: No | N16: 50 cm | P16: Installed | Q16: C
A17: 14 | B17: PLC-W101 | C17: WAGO CC100 751-9402 (KF10) | D17: Panel Cabinet | E17: X1 (ETH) | F17: WAGO 852-1812 Switch (KF1) | G17: Panel Cabinet | H17: LNK X3 | I17: SF/UTP Cat6a | J17: 4P | K17: 24 AWG | L17: 100V | M17: No | N17: 50 cm | P17: Installed | Q17: C
A18: 15 | B18: PLC-W102 | C18: WAGO CC100 751-9402 (KF10) | D18: Panel Cabinet | E18: X5:DIO1 / DIO2 / DIO3 | F18: P1 (Red) / P2 (Blue) / P3 (Green) Indicators | G18: Panel Cabinet | H18: Pin 1 (each) | I18: 3xAWG20 | J18: 3 | K18: 0.5 mm² | L18: 24V DC | M18: No | N18: 60 cm | P18: Installed | Q18: C
A19: 16 | B19: PLC-W103 | C19: P1 (Red) / P2 (Blue) / P3 (Green) Indicators | D19: Panel Cabinet | E19: Pin 2 (return, each) | F19: 0V DC Distribution Block (X0V) | G19: Panel Cabinet | H19: +-0V_P1/P2/P3_X1 | I19: 3xAWG20 | J19: 3 | K19: 0.5 mm² | L19: 24V DC | M19: No | N19: 60 cm | P19: Installed | Q19: C
A20: 17
A21: 18
A22: 19
A23: 20
A24: 21
A25: 22
A26: 23
A27: 24
A28: 25
A29: 26
A30: 27
A31: 28
... A53: 50

Sheet IO List
A1: ="SYSTEM I/O & POWER DISTRIBUTION LIST — "&Config!B6&" | "&Config!B11&" ("&Config!B12&")" -> SYSTEM I/O & POWER DISTRIBUTION LIST — PRJ-26001 | WAGO Compact Controller 100 (751-9402)
A2: # | B2: I/O Tag | C2: Description | D2: Cable / Wire No. | E2: Connector | F2: CODESYS Addr | G2: Channel Label | H2: Signal Type | I2: Range / State | J2: Wire + | K2: Wire - | L2: Screen | M2: Terminal | N2: Remarks
A3: DIGITAL INPUTS (DI) - 24 VDC | CC100: X12 (DI.1–DI.8)
A4: 1 | B4: X12:2 | C4: PLC 0V | D4: 20 AWG | H4: DC | I4: 0 VDC | K4: -X0V
A5: 2 | B5: X12:3 | C5: Button 24V | D5: 20 AWG | F5: %IX6.0 | H5: DI | I5: 24 VDC | J5: Button 24V
A6: 3
A7: 4
A8: 5
A9: DIGITAL OUTPUTS (DO) - 24 VDC | CC100: X5 (DIO channels configured as DO)
A10: 1 | B10: X5:3 | C10: Shneider Electric - Harmony XB5AVB4 (Red) | D10: 20 AWG | F10: %QX0.0 | I10: 24VDC
A11: 2 | B11: X5:4 | C11: Shneider Electric - Harmony XB5AVB6 (Blue) | D11: 20 AWG | F11: %QX0.1 | I11: 24VDC
A12: 3 | B12: X5:5 | C12: Shneider Electric - Harmony XB5AVB3 (Green) | D12: 20AWG | F12: %QX0.2 | I12: 24VDC
A13: 4
A14: 5
A15: ANALOG INPUTS (AI) - 4-20 mA / 0-10 V / NI1K / PT1K | CC100: X13 (AI, AIO) and X14 (NI/PT)
A16: 1
A17: 2
A18: 3
A19: 4
A20: 5
A21: ANALOG OUTPUTS (AO) - 4-20 mA / 0-10 V | CC100: X13 (AIO channels configured as AO)
A22: 1
A23: 2
A24: 3
A25: 4
A26: 5
A27: 24V DC BUS - POWER DISTRIBUTION | 5 Inputs / 5 Outputs
A28: 1 | B28: 24VIN-1 | C28: 24V DC Bus Input 1 | G28: 24V+ | H28: 24V DC | I28: 24V DC | J28: Red | K28: Black | L28: — | N28: 20 AWG
A29: 2 | B29: 24VIN-2 | C29: 24V DC Bus Input 2 | G29: 24V+ | H29: 24V DC | I29: 24V DC | J29: Red | K29: Black | L29: — | N29: 20 AWG
A30: 3 | B30: 24VIN-3 | C30: 24V DC Bus Input 3 | G30: 24V+ | H30: 24V DC | I30: 24V DC | J30: Red | K30: Black | L30: — | N30: 20 AWG
A31: 4 | B31: 24VIN-4 | C31: 24V DC Bus Input 4 | G31: 24V+ | H31: 24V DC | I31: 24V DC | J31: Red | K31: Black | L31: — | N31: 20 AWG
A32: 5 | B32: 24VIN-5 | C32: 24V DC Bus Input 5 | G32: 24V+ | H32: 24V DC | I32: 24V DC | J32: Red | K32: Black | L32: — | N32: 20 AWG
A33: 1 | B33: 24VOUT-1 | C33: 24V DC Bus Output 1 | G33: 24V+ | H33: 24V DC | I33: 24V DC | J33: Red | K33: Black | L33: — | N33: 20 AWG
A34: 2 | B34: 24VOUT-2 | C34: 24V DC Bus Output 2 | G34: 24V+ | H34: 24V DC | I34: 24V DC | J34: Red | K34: Black | L34: — | N34: 20 AWG
A35: 3 | B35: 24VOUT-3 | C35: 24V DC Bus Output 3 | G35: 24V+ | H35: 24V DC | I35: 24V DC | J35: Red | K35: Black | L35: — | N35: 20 AWG
A36: 4 | B36: 24VOUT-4 | C36: 24V DC Bus Output 4 | G36: 24V+ | H36: 24V DC | I36: 24V DC | J36: Red | K36: Black | L36: — | N36: 20 AWG
A37: 5 | B37: 24VOUT-5 | C37: 24V DC Bus Output 5 | G37: 24V+ | H37: 24V DC | I37: 24V DC | J37: Red | K37: Black | L37: — | N37: 20 AWG
A38: 0V DC BUS - POWER DISTRIBUTION | 5 Inputs / 5 Outputs
A39: 1 | B39: 0VIN-1 | C39: 0V DC Bus Input 1 | G39: 0V− | H39: 0V DC | I39: 0V DC | J39: Black | K39: — | L39: — | N39: 20 AWG
A40: 2 | B40: 0VIN-2 | C40: 0V DC Bus Input 2 | G40: 0V− | H40: 0V DC | I40: 0V DC | J40: Black | K40: — | L40: — | N40: 20 AWG
...

Sheet Terminal Block Layout
A1: ="TERMINAL BLOCK LAYOUT - "&Config!B6 -> TERMINAL BLOCK LAYOUT - PRJ-26001
A2: Panel ID: 1 | C2: Panel Name: PCW | E2: ="Voltage: "&Config!B19&" / "&Config!B20 -> Voltage: 24 VDC / 230 V AC, 50 Hz | H2: ="PLC: "&Config!B11&" ("&Config!B12&")" -> PLC: WAGO Compact Controller 100 (751-9402)
A3: DIN RAIL 1 - Power Supply & Earth Terminals
A4: TB No. | B4: Term No. | C4: Terminal Type | D4: Wire Color | E4: Cross-Section mm² | F4: Cable No. | G4: Cable Core | H4: To / From | I4: Tag / Description | J4: Ferrule | K4: Jumper | L4: Notes
A18: DIN RAIL 1 - Digital I/O Interface Terminals | CC100: X12 (DI.1–8) / X5 (DIO.1–8)
A19: TB No. | B19: Term No. | C19: Terminal Type | D19: Wire Color | E19: Cross-Section mm² | F19: Cable No. | G19: Cable Core | H19: To / From | I19: Tag / Description | J19: Ferrule | K19: Jumper | L19: Notes
A39: DIN RAIL 1 - Analog Signal Interface Terminals | CC100: X13 (AI/AIO) / X14 (NI/PT)
A40: TB No. | B40: Term No. | C40: Terminal Type | D40: Wire Color | E40: Cross-Section mm² | F40: Cable No. | G40: Cable Core | H40: To / From | I40: Tag / Description | J40: Ferrule | K40: Jumper | L40: Notes

Sheet Wiring Legend
A1: ="WIRING LEGEND, COLOR CODES & STANDARDS - "&Config!B6 -> WIRING LEGEND, COLOR CODES & STANDARDS - PRJ-26001
A3: 1. WIRE COLOR CODES — IEC 60446 / AS/NZS 3000
A4: Function | B4: Wire Color | C4: Hex Code | D4: IEC Ref | E4: Application | F4: Voltage Level | G4: Ferrule Color | H4: Notes
A5: 24V DC Positive | B5: Red | C5: #FF0000 | D5: IEC 60446 | E5: 24V DC Supply Positive | F5: 24V DC | G5: Red | H5: 20 AWG / 0.5mm²
A6: 0V DC Negative | B6: Black | C6: #000000 | D6: IEC 60446 | E6: 24V DC Supply Negative / Return | F6: 0V DC | G6: Black | H6: 20 AWG / 0.5mm²
A7: Protective Earth (PE) | B7: Green / Yellow | C7: #00B050 / #FFFF00 | D7: IEC 60446 | E7: Protective Earth / Safety Grounding | F7: 0V / Earth | G7: Green / Yellow | H7: 20 AWG / 0.5mm²
A8: Line (L) - AC Live | B8: Brown | C8: #843C0C | D8: IEC 60446 | E8: L - AC Line / Live Conductor | F8: 230V AC | G8: Brown | H8: 3G 1mm²
A9: Neutral (N) - AC Neutral | B9: Blue | C9: #2E75B6 | D9: IEC 60446 | E9: N - AC Neutral Conductor | F9: 0V AC | G9: Blue | H9: 3G 1mm²
A10: Protective Earth (PE) | B10: Green / Yellow | C10: #00B050 / #FFFF00 | D10: IEC 60446 | E10: Protective Earth / Safety Grounding | F10: 0V / Earth | G10: Green / Yellow | H10: 3G 1mm²
A19: 2. CABLE TYPE REFERENCE - SPECIFICATIONS
A20: Cable Code | B20: Cable Description | C20: Standard | D20: Outer Color | E20: Temp Range | F20: Application | G20: Min Bend Radius | H20: Notes
A32: 3. ABBREVIATIONS & TAG CODES
A33: Abbreviation | B33: Meaning | C33: Abbreviation | D33: Meaning
A51: 4. APPLICABLE STANDARDS & CODES
A52: Standard | B52: Title | C52: Applies To | D52: Notes
A53: IEC 60204-1 | B53: Safety of Machinery – Electrical Equipment | C53: Panel wiring, control circuits, safety | D53: Current edition
A54: IEC 60228 | B54: Conductors of Insulated Cables | C54: Wire sizing and classification
A55: IEC 60446 | B55: Identification of Conductors by Colours | C55: Wire colour coding | D55: Brown/Black/Grey/Blue/G-Y
A56: IEC 60502 | B56: Power Cables 1kV–30kV | C56: LV power cable specs | D56: XLPE and PVC
A57: IEC 60584 | B57: Thermocouples | C57: TC types and extension cables | D57: J, K, T, E type
A58: IEC 61131-2 | B58: PLCs – Equipment Requirements | C58: PLC hardware I/O specs | D58: Signal levels, filtering
A59: IEC 61156 | B59: Data Cables for Digital Communications | C59: Ethernet and comms cables | D59: Cat6 and RS485
A60: AS/NZS 3000 | B60: Wiring Rules (Australia/NZ) | C60: All electrical installations | D60: Local regulatory compliance
A61: AS/NZS 5000.1 | B61: Electric Cables – Polymeric Insulated | C61: LV power and control cables | D61: Australian cable standard
A62: IEC 61000-4-5 | B62: EMC – Surge Immunity | C62: Panel surge protection | D62: Cable segregation distances
A64: 5. WAGO CC100 (751-9402) I/O CONNECTOR REFERENCE
A65: Connector | B65: Channel(s) | C65: Signal Type | D65: CODESYS Address
A66: X11 | B66: DI.1 – DI.8 (8 channels) | C66: Digital Input 24VDC, sinking, 2.8 mA | D66: %IX0.0 – %IX0.7
A67: X12 | B67: DIO.1 – DIO.8 (8 channels) | C67: Configurable DI or DO 24VDC, 0.5 A | D67: %IX1.0–%IX1.7 / %QX1.0–%QX1.7
A68: X13 (AI) | B68: AI.1 – AI.2 (2 channels) | C68: Analog Input 4-20 mA / 0-10 V, 16-bit | D68: %IW0, %IW2
A69: X13 (AIO) | B69: AIO.1 – AIO.2 (2 channels) | C69: Configurable AI or AO 4-20 mA / 0-10 V | D69: %IW4, %IW6 / %QW0, %QW2
A70: X14 (NI/PT) | B70: NI.1 – NI.2 (2 channels) | C70: NI1000 / PT1000 RTD temperature input | D70: %IW8, %IW10
A71: RS-485 (×2) | B71: Port 1 and Port 2 | C71: RS-485 serial: Modbus RTU, custom serial | D71: SysLibCom / ModbusRTU lib
A72: Ethernet (×2) | B72: X1 (ETH1), X2 (ETH2) | C72: Modbus TCP, PROFINET, EtherCAT, BACnet, MQTT | D72: Configured via WBM / CODESYS

Sheet Cable Drum Register
A1: ="CABLE DRUM REGISTER - "&Config!B6 -> CABLE DRUM REGISTER - PRJ-26001
A2: ="Project: "&Config!B6&" | Site: "&Config!B8&" | Maintained By: Electrical Foreman" -> Project: PRJ-26001 | Site: Building J - Cyber3Lab, Howest Brugge, Belgium | Maintained By: Electrical Foreman
A3: # | B3: Drum ID | C3: Cable Type & Spec | D3: Core Qty | E3: Core Size | F3: Volt Rating | G3: Full Length (m) | H3: Issued (m) | I3: Remaining (m) | J3: Location / Bay | K3: Date Received | L3: Supplier | M3: Remarks
A4: 1 | I4: =IF(G4="","",G4-H4)
A5: 2 | I5: =IF(G5="","",G5-H5)
A6: 3 | I6: =IF(G6="","",G6-H6)
A7: 4 | I7: =IF(G7="","",G7-H7)
A8: 5 | I8: =IF(G8="","",G8-H8)
A9: 6 | I9: =IF(G9="","",G9-H9)
A10: 7 | I10: =IF(G10="","",G10-H10)
A11: 8 | I11: =IF(G11="","",G11-H11)
A12: 9 | I12: =IF(G12="","",G12-H12)
A13: 10 | I13: =IF(G13="","",G13-H13)
A14: 11 | I14: =IF(G14="","",G14-H14)
A15: 12 | I15: =IF(G15="","",G15-H15)
... A28: 25 | I28: =IF(G28="","",G28-H28)
