Workbook

Sheet Config
A1: PROJECT CONFIGURATION — VARIABLE DEFINITIONS
A2: All sheets reference these cells. Change a value here and it propagates everywhere automatically.
A3: SECTION 1 — PROJECT IDENTITY
A4: Variable Name | B4: Value | C4: Unit / Notes | D4: Used In | E4: Updated | F4: Source
A5: ProjectName | B5: Galvanizing System | C5: Project Title | D5: All Sheets | E5: 2025 | F5: Client Brief
A6: ProjectNumber | B6: PRJ-26001 | C6: Project ID | D6: All Sheets – Headers | E6: 2025 | F6: PM System
A7: ClientName | B7: Howest - Cyber3Lab | C7: Client | D7: Cover | E7: 2025 | F7: Contract
A8: SiteLocation | B8: Building J - Cyber3Lab, Howest Brugge, Belgium | C8: Location | D8: Cover, TBL | E8: 2025 | F8: Site Survey
A9: SECTION 2 — PLC PLATFORM (WAGO CC100 751-9402)
A10: Variable Name | B10: Value | C10: Unit / Notes | D10: Used In | E10: Updated | F10: Source
A11: PLCPlatform | B11: WAGO Compact Controller 100 | C11: Brand / Series | D11: Cover, IO List, TBL | E11: 2025 | F11: WAGO 751-9402 Datasheet
A12: PLCModelNo | B12: 751-9402 | C12: Part Number | D12: Cover, IO List, TBL | E12: 2025 | F12: wago.com/global/p/751-9402
A13: PLCProgEnv | B13: CODESYS V3.5 | C13: IDE / Runtime | D13: Cover, Wiring Legend | E13: 2025 | F13: WAGO firmware docs
A14: PLCComms | B14: Modbus TCP, EtherNet/IP, PROFINET, EtherCAT, BACnet, MQTT | C14: Protocols | D14: Cover, Legend | E14: 2025 | F14: WAGO product page
A15: PLCConnType | B15: picoMAX® CAGE CLAMP® push-in | C15: I/O Connector Type | D15: IO List, TBL | E15: 2025 | F15: WAGO datasheet
A16: PLCRating | B16: IP20 / DIN Rail Mount / 24 VDC | C16: Protection / Mounting | D16: Cover, TBL | E16: 2025 | F16: WAGO 751-9402 spec
A17: SECTION 3 — ELECTRICAL SPECIFICATIONS
A18: Variable Name | B18: Value | C18: Unit / Notes | D18: Used In | E18: Updated | F18: Source
A19: VoltageControl | B19: 24 VDC | C19: Control Supply | D19: Cover, IO List, TBL, Legend | E19: 2025 | F19: IEC 60204-1
A20: VoltagePower | B20: 400 VAC, 3-Phase, 50 Hz | C20: Main Supply | D20: Cover, TBL | E20: 2025 | F20: Site supply spec
A21: EnclosureRating | B21: IP65 (Field) / IP54 (Panel) | C21: IP Rating | D21: Cover, TBL | E21: 2025 | F21: IEC 60529
A22: SECTION 4 — WAGO CC100 I/O CHANNEL MAP (On-Board I/O)
A23: Variable Name | B23: Value | C23: Unit / Notes | D23: Used In | E23: Updated | F23: Source
A24: I/O Tag | B24: Channel Label | C24: CODESYS Addr | D24: Signal Type | E24: Connector | F24: Notes
A25: DI10001 | B25: DI.1 | C25: %IX0.0 | D25: DI 24VDC | E25: X11 – Pin 1 | F25: On-board: 8 dedicated DI, 2.8 mA
A26: DI10002 | B26: DI.2 | C26: %IX0.1 | D26: DI 24VDC | E26: X11 – Pin 2 | F26: 24 VDC sinking, RC filter 5µs
A27: DI10003 | B27: DI.3 | C27: %IX0.2 | D27: DI 24VDC | E27: X11 – Pin 3
A28: DI10004 | B28: DI.4 | C28: %IX0.3 | D28: DI 24VDC | E28: X11 – Pin 4
A29: DI10005 | B29: DI.5 | C29: %IX0.4 | D29: DI 24VDC | E29: X11 – Pin 5
A30: DI10006 | B30: DI.6 | C30: %IX0.5 | D30: DI 24VDC | E30: X11 – Pin 6
A31: DI10007 | B31: DI.7 | C31: %IX0.6 | D31: DI 24VDC | E31: X11 – Pin 7
A32: DI10008 | B32: DI.8 | C32: %IX0.7 | D32: DI 24VDC | E32: X11 – Pin 8
A33: DI10009 | B33: DIO.1 | C33: %IX1.0 | D33: DI/DO 24VDC | E33: X12 – Pin 1 | F33: 8 configurable DIO; set in CODESYS
A34: DI10010 | B34: DIO.2 | C34: %IX1.1 | D34: DI/DO 24VDC | E34: X12 – Pin 2 | F34: Configure as DI or DO per channel
A35: DI10011 | B35: DIO.3 | C35: %IX1.2 | D35: DI/DO 24VDC | E35: X12 – Pin 3
A36: DI10012 | B36: DIO.4 | C36: %IX1.3 | D36: DI/DO 24VDC | E36: X12 – Pin 4
A37: DO20001 | B37: DIO.5 | C37: %QX1.4 | D37: DO 24VDC | E37: X12 – Pin 5 | F37: Configured as DO, 0.5 A max
A38: DO20002 | B38: DIO.6 | C38: %QX1.5 | D38: DO 24VDC | E38: X12 – Pin 6
A39: DO20003 | B39: DIO.7 | C39: %QX1.6 | D39: DO 24VDC | E39: X12 – Pin 7
A40: DO20004 | B40: DIO.8 | C40: %QX1.7 | D40: DO 24VDC | E40: X12 – Pin 8
...

Sheet Cover
B1: INDUSTRIAL PLC CABLING & WIRING SYSTEM
B2: Project Documentation Package
B4: PROJECT INFORMATION
B5: Project Name: | C5: =Config!B5 -> Galvanizing System | D5: Project No.: | E5: =Config!B6 -> PRJ-26001
B6: Client: | C6: =Config!B7 -> Howest - Cyber3Lab | D6: Site Location: | E6: =Config!B8 -> Building J - Cyber3Lab, Howest Brugge, Belgium
B7: Engineer: | C7: =Config!B61 -> Attila Peter Szucs | D7: Discipline: | E7: =Config!B62 -> Electrical / Instrumentation
B8: Drawing Ref: | C8: =Config!B57 -> EL-PLC-001 to EL-PLC-048 | D8: PLC Platform: | E8: =Config!B11&" ("&Config!B12&")" -> WAGO Compact Controller 100 (751-9402)
B9: Voltage (Control): | C9: =Config!B19 -> 24 VDC | D9: Voltage (Power): | E9: =Config!B20 -> 400 VAC, 3-Phase, 50 Hz
B10: Enclosure Rating: | C10: =Config!B21 -> IP65 (Field) / IP54 (Panel) | D10: Standard: | E10: IEC 60204-1 / AS/NZS 3000
B11: Prepared By: | C11: =Config!B58 -> Howest - Cyber3Lab | D11: Date:
B12: Approved By: | C12: =Config!B59 -> Laurens Singier | D12: Rev Status: | E12: =Config!B60 -> REV A – Issued for Construction
B14: DOCUMENT INDEX
B15: Sheet / Tab | C15: Document Title | D15: Description | E15: Status
B16: Cover | C16: Project Cover Sheet | D16: Project information and document index
B17: Cable Schedule | C17: Cable Schedule | D17: Full cable listing with specs, routing & terminations
B18: IO List | C18: PLC I/O List | D18: Digital and analog I/O assignments with signal details
B19: Terminal Block Layout | C19: Terminal Block Layout | D19: Panel terminal block assignments and wire mapping
B20: Cable Drum Register | C20: Cable Drum Register | D20: Drum tracking, lengths issued and remaining
B21: Wiring Legend | C21: Wiring Legend & Standards | D21: Color codes, abbreviations, cable types, standards ref
B23: GENERAL NOTES
B24: 1. All cabling shall be installed in accordance with IEC 60204-1 and local wiring regulations.
B25: 2. Signal cables (4–20 mA) must be segregated from power cables (minimum 200 mm separation).
B26: 3. All cable screens/shields to be grounded at ONE end only (control panel end) unless otherwise noted.
B27: 4. Minimum cable bending radius: 6× cable OD (multi-core), 8× cable OD (armoured).
B28: 5. All field terminations to use ferrules (bootlace type). Crimping tool: Weidmuller or equivalent.
B29: 6. WAGO CC100 I/O: 8 DI (X11), 8 configurable DIO (X12), 2 AI + 2 AIO (X13), 2 NI/PT (X14). All on-board; 24 VDC.
B30: 7. Motor cables must be shielded (VFD duty) where inverter drives are installed.
B31: 8. [Add project-specific notes here]

Sheet Cable Schedule
A1: ="CABLE SCHEDULE — "&Config!B6 -> CABLE SCHEDULE — PRJ-26001
A2: ="Project: "&Config!B6&" | Project No: "&Config!B6&" | PLC: "&Config!B11&" ("&Config!B12&") | Rev: "&Config!B60 -> Project: PRJ-26001 | Project No: PRJ-26001 | PLC: WAGO Compact Controller 100 (751-9402) | Rev: REV A – Issued for Construction
A3: # | B3: Cable No. | C3: From (Source) | D3: From Location | E3: From Terminal | F3: To (Destination) | G3: To Location | H3: To Terminal | I3: Cable Type | J3: Cores | K3: Size mm² | L3: Volt Rating | M3: Shield | N3: Length m | O3: Conduit / Tray | P3: Status | Q3: Rev
A4: 1
A5: 2
A6: 3
A7: 4
A8: 5
A9: 6
A10: 7
A11: 8
A12: 9
A13: 10
A14: 11
A15: 12
... A53: 50

Sheet IO List
A1: ="PLC I/O LIST — "&Config!B6&" | "&Config!B11&" ("&Config!B12&")" -> PLC I/O LIST — PRJ-26001 | WAGO Compact Controller 100 (751-9402)
A2: # | B2: I/O Tag | C2: Description | D2: Cable No. | E2: Connector | F2: CODESYS Addr | G2: Channel Label | H2: Signal Type | I2: Range / State | J2: Wire + | K2: Wire - | L2: Screen | M2: Terminal | N2: Remarks
A3: DIGITAL INPUTS (DI) — 24 VDC | CC100: X11 (DI.1–DI.8) and X12 (DIO.1–DIO.8 configurable as DI)
A4: 1
A5: 2
A6: 3
A7: 4
A8: 5
A9: 6
A10: 7
A11: 8
A12: 9
A13: 10
A14: 11
A15: 12
... A19: 16
A20: DIGITAL OUTPUTS (DO) — 24 VDC | CC100: X12 (DIO channels configured as DO)
A21: 1
A22: 2
A23: 3
A24: 4
A25: 5
A26: 6
A27: 7
A28: 8
A29: ANALOG INPUTS (AI) — 4-20 mA / 0-10 V / NI1K / PT1K | CC100: X13 (AI, AIO) and X14 (NI/PT)
A30: 1
A31: 2
A32: 3
A33: 4
A34: 5
A35: 6
A36: 7
A37: 8
A38: ANALOG OUTPUTS (AO) — 4-20 mA / 0-10 V | CC100: X13 (AIO channels configured as AO)
A39: 1
A40: 2
A41: 3
A42: 4
A43: 5

Sheet Terminal Block Layout
A1: ="TERMINAL BLOCK LAYOUT — "&Config!B6 -> TERMINAL BLOCK LAYOUT — PRJ-26001
A2: Panel ID: | C2: Panel Name: | E2: ="Voltage: "&Config!B19&" / "&Config!B20 -> Voltage: 24 VDC / 400 VAC, 3-Phase, 50 Hz | H2: ="PLC: "&Config!B11&" ("&Config!B12&")" -> PLC: WAGO Compact Controller 100 (751-9402)
A4: DIN RAIL 1 — Power Supply & Earth Terminals
A5: TB No. | B5: Term No. | C5: Terminal Type | D5: Wire Color | E5: Cross-Section mm² | F5: Cable No. | G5: Cable Core | H5: To / From | I5: Tag / Description | J5: Ferrule | K5: Jumper | L5: Notes
A19: DIN RAIL 2 — Digital I/O Interface Terminals | CC100: X11 (DI.1–8) / X12 (DIO.1–8)
A20: TB No. | B20: Term No. | C20: Terminal Type | D20: Wire Color | E20: Cross-Section mm² | F20: Cable No. | G20: Cable Core | H20: To / From | I20: Tag / Description | J20: Ferrule | K20: Jumper | L20: Notes
A40: DIN RAIL 3 — Analog Signal Interface Terminals | CC100: X13 (AI/AIO) / X14 (NI/PT)
A41: TB No. | B41: Term No. | C41: Terminal Type | D41: Wire Color | E41: Cross-Section mm² | F41: Cable No. | G41: Cable Core | H41: To / From | I41: Tag / Description | J41: Ferrule | K41: Jumper | L41: Notes

Sheet Cable Drum Register
A1: ="CABLE DRUM REGISTER — "&Config!B6 -> CABLE DRUM REGISTER — PRJ-26001
A2: ="Project: "&Config!B6&" | Site: "&Config!B8&" | Maintained By: Electrical Foreman" -> Project: PRJ-26001 | Site: Building J - Cyber3Lab, Howest Brugge, Belgium | Maintained By: Electrical Foreman
A3: # | B3: Drum ID | C3: Cable Type & Spec | D3: Core Qty | E3: Core Size | F3: Volt Rating | G3: Full Length (m) | H3: Issued (m) | I3: Remaining (m) | J3: Location / Bay | K3: Date Received | L3: Supplier | M3: Remarks
A4: 1 | I4: =IF(G4="","",G4-H4)
A5: 2 | I5: =IF(G5="","",G5-H5)
A6: 3 | I6: =IF(G6="","",G6-H6)
A7: 4 | I7: =IF(G7="","",G7-H7)
A8: 5 | I8: =IF(G8="","",G8-H8)
A9: 6 | I9: =IF(G9="","",G9-H9)
A10: 7 | I10: =IF(G10="","",G10-H10)
A11: 8 | I11: =IF(G11="","",G11-H11)
A12: 9 | I12: =IF(G12="","",G12-H12)
A13: 10 | I13: =IF(G13="","",G13-H13)
A14: 11 | I14: =IF(G14="","",G14-H14)
A15: 12 | I15: =IF(G15="","",G15-H15)
... A28: 25 | I28: =IF(G28="","",G28-H28)

Sheet Wiring Legend
A1: ="WIRING LEGEND, COLOR CODES & STANDARDS — "&Config!B6 -> WIRING LEGEND, COLOR CODES & STANDARDS — PRJ-26001
A3: 1. WIRE COLOR CODES — IEC 60446 / AS/NZS 3000
A4: Function | B4: Wire Color | C4: Hex Code | D4: IEC Ref | E4: Application | F4: Voltage Level | G4: Ferrule Color | H4: Notes
A18: 2. CABLE TYPE REFERENCE — SPECIFICATIONS
A19: Cable Code | B19: Cable Description | C19: Standard | D19: Outer Color | E19: Temp Range | F19: Application | G19: Min Bend Radius | H19: Notes
A31: 3. ABBREVIATIONS & TAG CODES
A32: Abbreviation | B32: Meaning | C32: Abbreviation | D32: Meaning
A50: 4. APPLICABLE STANDARDS & CODES
A51: Standard | B51: Title | C51: Applies To | D51: Notes
A52: IEC 60204-1 | B52: Safety of Machinery – Electrical Equipment | C52: Panel wiring, control circuits, safety | D52: Current edition
A53: IEC 60228 | B53: Conductors of Insulated Cables | C53: Wire sizing and classification
A54: IEC 60446 | B54: Identification of Conductors by Colours | C54: Wire colour coding | D54: Brown/Black/Grey/Blue/G-Y
A55: IEC 60502 | B55: Power Cables 1kV–30kV | C55: LV power cable specs | D55: XLPE and PVC
A56: IEC 60584 | B56: Thermocouples | C56: TC types and extension cables | D56: J, K, T, E type
A57: IEC 61131-2 | B57: PLCs – Equipment Requirements | C57: PLC hardware I/O specs | D57: Signal levels, filtering
A58: IEC 61156 | B58: Data Cables for Digital Communications | C58: Ethernet and comms cables | D58: Cat6 and RS485
A59: AS/NZS 3000 | B59: Wiring Rules (Australia/NZ) | C59: All electrical installations | D59: Local regulatory compliance
A60: AS/NZS 5000.1 | B60: Electric Cables – Polymeric Insulated | C60: LV power and control cables | D60: Australian cable standard
A61: IEC 61000-4-5 | B61: EMC – Surge Immunity | C61: Panel surge protection | D61: Cable segregation distances
A63: 5. WAGO CC100 (751-9402) I/O CONNECTOR REFERENCE
A64: Connector | B64: Channel(s) | C64: Signal Type | D64: CODESYS Address
A65: X11 | B65: DI.1 – DI.8 (8 channels) | C65: Digital Input 24VDC, sinking, 2.8 mA | D65: %IX0.0 – %IX0.7
A66: X12 | B66: DIO.1 – DIO.8 (8 channels) | C66: Configurable DI or DO 24VDC, 0.5 A | D66: %IX1.0–%IX1.7 / %QX1.0–%QX1.7
A67: X13 (AI) | B67: AI.1 – AI.2 (2 channels) | C67: Analog Input 4-20 mA / 0-10 V, 16-bit | D67: %IW0, %IW2
A68: X13 (AIO) | B68: AIO.1 – AIO.2 (2 channels) | C68: Configurable AI or AO 4-20 mA / 0-10 V | D68: %IW4, %IW6 / %QW0, %QW2
A69: X14 (NI/PT) | B69: NI.1 – NI.2 (2 channels) | C69: NI1000 / PT1000 RTD temperature input | D69: %IW8, %IW10
A70: RS-485 (×2) | B70: Port 1 and Port 2 | C70: RS-485 serial: Modbus RTU, custom serial | D70: SysLibCom / ModbusRTU lib
A71: Ethernet (×2) | B71: X1 (ETH1), X2 (ETH2) | C71: Modbus TCP, PROFINET, EtherCAT, BACnet, MQTT | D71: Configured via WBM / CODESYS
